Workbook

Sheet DATOS HISTÓRICOS
A1: =B12 & " - " & E12 -> 12 - 14 | G1: MÁXIMOS GOLEADORES HISTÓRICOS
G2: Jugador | H2: Cant. goles | I2: Equipo
G3: =IFERROR(__xludf.DUMMYFUNCTION("IFERROR(SORTN(FILTER({N27:P120; R27:T120}, {O27:O120; S27:S120} <> """"), 10, 0, 2, FALSE), """")"),"Luis Diaz") -> Luis Diaz | H3: =IFERROR(__xludf.DUMMYFUNCTION("""COMPUTED_VALUE"""),37.0) -> 37 | I3: =IFERROR(__xludf.DUMMYFUNCTION("""COMPUTED_VALUE"""),"(SDC)") -> (SDC)
G4: =IFERROR(__xludf.DUMMYFUNCTION("""COMPUTED_VALUE"""),"Van Basten") -> Van Basten | H4: =IFERROR(__xludf.DUMMYFUNCTION("""COMPUTED_VALUE"""),36.0) -> 36 | I4: =IFERROR(__xludf.DUMMYFUNCTION("""COMPUTED_VALUE""")," (VDG)") -> (VDG)
G5: =IFERROR(__xludf.DUMMYFUNCTION("""COMPUTED_VALUE"""),"Havertz") -> Havertz | H5: =IFERROR(__xludf.DUMMYFUNCTION("""COMPUTED_VALUE"""),36.0) -> 36 | I5: =IFERROR(__xludf.DUMMYFUNCTION("""COMPUTED_VALUE"""),"(SDC)") -> (SDC)
G6: =IFERROR(__xludf.DUMMYFUNCTION("""COMPUTED_VALUE"""),"Shevchenko") -> Shevchenko | H6: =IFERROR(__xludf.DUMMYFUNCTION("""COMPUTED_VALUE"""),14.0) -> 14 | I6: =IFERROR(__xludf.DUMMYFUNCTION("""COMPUTED_VALUE""")," (VDG)") -> (VDG)
G7: =IFERROR(__xludf.DUMMYFUNCTION("""COMPUTED_VALUE"""),"Van Nistelrooij") -> Van Nistelrooij | H7: =IFERROR(__xludf.DUMMYFUNCTION("""COMPUTED_VALUE"""),13.0) -> 13 | I7: =IFERROR(__xludf.DUMMYFUNCTION("""COMPUTED_VALUE""")," (VDG)") -> (VDG)
G8: =IFERROR(__xludf.DUMMYFUNCTION("""COMPUTED_VALUE"""),"Mbappe") -> Mbappe | H8: =IFERROR(__xludf.DUMMYFUNCTION("""COMPUTED_VALUE"""),10.0) -> 10 | I8: =IFERROR(__xludf.DUMMYFUNCTION("""COMPUTED_VALUE""")," (VDG)") -> (VDG)
G9: =IFERROR(__xludf.DUMMYFUNCTION("""COMPUTED_VALUE"""),"Dani Olmo") -> Dani Olmo | H9: =IFERROR(__xludf.DUMMYFUNCTION("""COMPUTED_VALUE"""),10.0) -> 10 | I9: =IFERROR(__xludf.DUMMYFUNCTION("""COMPUTED_VALUE"""),"(SDC)") -> (SDC)
G10: =IFERROR(__xludf.DUMMYFUNCTION("""COMPUTED_VALUE"""),"Van Nistelrooy") -> Van Nistelrooy | H10: =IFERROR(__xludf.DUMMYFUNCTION("""COMPUTED_VALUE"""),7.0) -> 7 | I10: =IFERROR(__xludf.DUMMYFUNCTION("""COMPUTED_VALUE"""),"(SDC)") -> (SDC)
G11: =IFERROR(__xludf.DUMMYFUNCTION("""COMPUTED_VALUE"""),"Vieri") -> Vieri | H11: =IFERROR(__xludf.DUMMYFUNCTION("""COMPUTED_VALUE"""),7.0) -> 7 | I11: =IFERROR(__xludf.DUMMYFUNCTION("""COMPUTED_VALUE"""),"(SDC)") -> (SDC)
A12: Triunfos | B12: ='TEMPORADA 1'!I54 + 'TEMPORADA 2'!I54 -> 12 | C12: Total partidos | D12: Triunfos | E12: ='TEMPORADA 1'!L54 + 'TEMPORADA 2'!L54 -> 14 | G12: =IFERROR(__xludf.DUMMYFUNCTION("""COMPUTED_VALUE"""),"Dembele") -> Dembele | H12: =IFERROR(__xludf.DUMMYFUNCTION("""COMPUTED_VALUE"""),6.0) -> 6 | I12: =IFERROR(__xludf.DUMMYFUNCTION("""COMPUTED_VALUE""")," (VDG)") -> (VDG)
A13: Derrotas | B13: ='TEMPORADA 1'!I55 + 'TEMPORADA 2'!I55 -> 14 | C13: =B12+E12+B14 -> 30 | D13: Derrotas | E13: =B12 -> 12
A14: Empates | B14: ='TEMPORADA 1'!I56 + 'TEMPORADA 2'!I56 -> 4 | C14: Series empate | D14: Empates | E14: 4
A15: Historial | B15: ='TEMPORADA 1'!I57 + 'TEMPORADA 2'!I57 -> -2 | C15: 2 | D15: Historial | E15: =E12-E13 -> 2
A16: MAYOR VICTORIA | B16: 46122 | D16: MAYOR VICTORIA | E16: 46091
A17: TOTAL GOLES | B17: ='TEMPORADA 1'!I59 + 'TEMPORADA 2'!I59 -> 115 | D17: TOTAL GOLES | E17: =SUM(S27:S120) -> 130
A18: SERIES GANADAS | B18: ='TEMPORADA 1'!I60 + 'TEMPORADA 2'!I60 -> 6 | D18: SERIES GANADAS | E18: 7
A19: =B12 -> 12 | B19: A FAVOR DE: | C19: =IF(E13 > B13, "VIUDAS DE GALLARDO", IF(B13 > E13, "SOLDADO DE COUDET", "¡EMPATE HISTÓRICO!")) -> SOLDADO DE COUDET | E19: =E12 -> 14
A20: =IFERROR(__xludf.DUMMYFUNCTION("SPARKLINE({B12, B14*1, E12}, {""charttype"", ""bar""; ""color1"", ""#202020""; ""color2"", ""#A0A0A0""; ""color3"", ""#FFFFFF""})"),"")
A22: GANADORES BALON DE ORO TODAS LAS TEMPORADAS
A23: 1ra temporada: KAI HAVERTZ (SOLDADO DE COUDET) | E23: 2da temporada: ?
N27: {=UNIQUE({'TEMPORADA 1'!A4:A50; 'TEMPORADA 2'!A4:A50})} -> Khan | O27: {=IF(N27:N120="", "", SUMIF('TEMPORADA 1'!A$4:A$50, N27:N120, 'TEMPORADA 1'!B$4:B$50) + SUMIF('TEMPORADA 2'!A$4:A$50, N27:N120, 'TEMPORADA 2'!B$4:B$50))} -> 4 | P27: {=IF(N27:N120="", "", 'TEMPORADA 2'!$C$2)} -> (VDG) | R27: {=UNIQUE({'TEMPORADA 1'!L4:L41; 'TEMPORADA 2'!L4:L41})} -> Cech | S27: {=IF(R27:R120="", "", SUMIF('TEMPORADA 1'!L$4:L$41, R27:R120, 'TEMPORADA 1'!M$4:M$50) + SUMIF('TEMPORADA 2'!L$4:L$41, R27:R120, 'TEMPORADA 2'!M$4:M$50))} -> 0 | T27: {=IF(R27:R120="", "", 'TEMPORADA 2'!$N$2)} -> (SDC)
N28: Peruzzi | O28: 0 | P28: (VDG) | R28: Puyol | S28: 0 | T28: (SDC)
N29: Van Dijk | O29: 0 | P29: (VDG) | R29: Vermaelen | S29: 0 | T29: (SDC)
N30: Mancini | O30: 0 | P30: (VDG) | R30: Beckenbauer | S30: 0 | T30: (SDC)
N31: Saliba | O31: 0 | P31: (VDG) | R31: Bastoni | S31: 0 | T31: (SDC)
N32: Huijsen | O32: 0 | P32: (VDG) | R32: Kounde | S32: 0 | T32: (SDC)
N33: Matty Cash | O33: 2 | P33: (VDG) | R33: Silvestre | S33: 0 | T33: (SDC)
N34: Grimaldo | O34: 1 | P34: (VDG) | R34: Gvardiol | S34: 0 | T34: (SDC)
N35: Rijkaard | O35: 0 | P35: (VDG) | R35: Cafú | S35: 2 | T35: (SDC)
N36: Declan Rice | O36: 1 | P36: (VDG) | R36: Tonali | S36: 1 | T36: (SDC)
N37: Pedri | O37: 3 | P37: (VDG) | R37: Fletcher | S37: 0 | T37: (SDC)
N38: Mac Allister | O38: 0 | P38: (VDG) | R38: Rodri | S38: 0 | T38: (SDC)
N39: Odegaard | O39: 2 | P39: (VDG) | R39: Mac Allister | S39: 4 | T39: (SDC)
... N55: Van Nistelrooij | O55: 13 | P55: (VDG) | R55: Paredes | S55: 0 | T55: (SDC)
N56: Osimhen | O56: 0 | P56: (VDG)
N57: J. Alvarez | O57: 0 | P57: (VDG)
N58: Montiel | O58: 0 | P58: (VDG)
N59: Silvestre | O59: 0 | P59: (VDG)
...

Sheet TEMPORADA 1
A1: SUPERCLASICO PES
A2: VIUDAS DE GALLARDO | C2: (VDG) | I2: CRITERIOS BALÓN DE ORO | L2: SOLDADO DE COUDET | N2: (SDC)
A3: JUGADORES | B3: CANT. GOLES | C3: MVP's | D3: JUGADOS | E3: PROM. GOL | F3: TARJ. ROJAS | G3: TARJ. AMARILLA | H3: PBDO | I3: MVP | K3: suma 3 | L3: JUGADORES | M3: CANT. GOLES | N3: MVP´s | O3: JUGADOS | P3: PROM. GOL | Q3: TARJ. ROJAS | R3: TARJ. AMARILLA | S3: PBDO
A4: Khan | B4: 4 | C4: 0 | D4: 29 | E4: =IFERROR(B4/D4, 0) -> 0.13793103 | F4: 0 | G4: 0 | H4: =(B4)+(C4*3)-G4-(F4*2) -> 4 | I4: GOL | K4: suma 1 | L4: Cech | M4: 0 | N4: 0 | O4: 28 | P4: =IFERROR(M4/O4, 0) -> 0 | Q4: 0 | R4: 0 | S4: =(M4*1)+(N4*3)-(Q4*2)-R4 -> 0
A5: Peruzzi | B5: 0 | C5: 0 | D5: 0 | E5: =IFERROR(B5/D5, 0) -> 0 | F5: 0 | G5: 0 | H5: =(B5*1)+(C5*3)-(F5*2)-G5 -> 0 | I5: AMARILLA | K5: resta 1 | L5: Puyol | M5: 0 | N5: 0 | O5: 18 | P5: =IFERROR(M5/O5, 0) -> 0 | Q5: 1 | R5: 0 | S5: =(M5*1)+(N5*3)-(Q5*2)-R5 -> -2
A6: Van Dijk | B6: 0 | C6: 0 | D6: 29 | E6: =IFERROR(B6/D6, 0) -> 0 | F6: 1 | G6: 0 | H6: =(B6*1)+(C6*3)-(F6*2)-G6 -> -2 | I6: ROJA | K6: resta 2 | L6: Vermaelen | M6: 0 | N6: 0 | O6: 22 | P6: =IFERROR(M6/O6, 0) -> 0 | Q6: 2 | R6: 0 | S6: =(M6*1)+(N6*3)-(Q6*2)-R6 -> -4
A7: Mancini | B7: 0 | C7: 0 | D7: 25 | E7: =IFERROR(B7/D7, 0) -> 0 | F7: 1 | G7: 0 | H7: =(B7*1)+(C7*3)-(F7*2)-G7 -> -2 | L7: Beckenbauer | M7: 0 | N7: 0 | O7: 20 | P7: =IFERROR(M7/O7, 0) -> 0 | Q7: 0 | R7: 0 | S7: =(M7*1)+(N7*3)-(Q7*2)-R7 -> 0
A8: Saliba | B8: 0 | C8: 0 | D8: 4 | E8: =IFERROR(B8/D8, 0) -> 0 | F8: 0 | G8: 0 | H8: =(B8*1)+(C8*3)-(F8*2)-G8 -> 0 | I8: Suma de puntos Balón de ORO | L8: Bastoni | M8: 0 | N8: 0 | O8: 17 | P8: =IFERROR(M8/O8, 0) -> 0 | Q8: 0 | R8: 0 | S8: =(M8*1)+(N8*3)-(Q8*2)-R8 -> 0
A9: Huijsen | B9: 0 | C9: 0 | D9: 8 | E9: =IFERROR(B9/D9, 0) -> 0 | F9: 0 | G9: 0 | H9: =(B9*1)+(C9*3)-(F9*2)-G9 -> 0 | I9: Jugador | J9: Puntaje | K9: Equipo | L9: Kounde | M9: 0 | N9: 0 | O9: 3 | P9: =IFERROR(M9/O9, 0) -> 0 | Q9: 0 | R9: 0 | S9: =(M9*1)+(N9*3)-(Q9*2)-R9 -> 0
A10: Matty Cash | B10: 2 | C10: 0 | D10: 25 | E10: =IFERROR(B10/D10, 0) -> 0.08 | F10: 0 | G10: 0 | H10: =(B10*1)+(C10*3)-(F10*2)-G10 -> 2 | I10: =IFERROR(__xludf.DUMMYFUNCTION("IFERROR(SORTN(FILTER({A4:A40, H4:H40, IF(A4:A40="""", """", C2); L4:L40, S4:S40, IF(L4:L40="""", """", N2)}, {H4:H40; S4:S40} > 0), 10, 0, 2, FALSE), """")"),"Luis Diaz") -> Luis Diaz | J10: =IFERROR(__xludf.DUMMYFUNCTION("""COMPUTED_VALUE"""),37.0) -> 37 | K10: =IFERROR(__xludf.DUMMYFUNCTION("""COMPUTED_VALUE"""),"(SDC)") -> (SDC) | L10: Silvestre | M10: 0 | N10: 0 | O10: 16 | P10: =IFERROR(M10/O10, 0) -> 0 | Q10: 0 | R10: 0 | S10: =(M10*1)+(N10*3)-(Q10*2)-R10 -> 0
A11: Grimaldo | B11: 1 | C11: 0 | D11: 26 | E11: =IFERROR(B11/D11, 0) -> 0.038461538 | F11: 0 | G11: 0 | H11: =(B11*1)+(C11*3)-(F11*2)-G11 -> 1 | I11: =IFERROR(__xludf.DUMMYFUNCTION("""COMPUTED_VALUE"""),"Van Basten") -> Van Basten | J11: =IFERROR(__xludf.DUMMYFUNCTION("""COMPUTED_VALUE"""),36.0) -> 36 | K11: =IFERROR(__xludf.DUMMYFUNCTION("""COMPUTED_VALUE""")," (VDG)") -> (VDG) | L11: Gvardiol | M11: 0 | N11: 0 | O11: 18 | P11: =IFERROR(M11/O11, 0) -> 0 | Q11: 0 | R11: 0 | S11: =(M11*1)+(N11*3)-(Q11*2)-R11 -> 0
A12: Rijkaard | B12: 0 | C12: 0 | D12: 29 | E12: =IFERROR(B12/D12, 0) -> 0 | F12: 0 | G12: 0 | H12: =(B12*1)+(C12*3)-(F12*2)-G12 -> 0 | I12: =IFERROR(__xludf.DUMMYFUNCTION("""COMPUTED_VALUE"""),"Havertz") -> Havertz | J12: =IFERROR(__xludf.DUMMYFUNCTION("""COMPUTED_VALUE"""),32.0) -> 32 | K12: =IFERROR(__xludf.DUMMYFUNCTION("""COMPUTED_VALUE"""),"(SDC)") -> (SDC) | L12: Cafú | M12: 2 | N12: 0 | O12: 26 | P12: =IFERROR(M12/O12, 0) -> 0.076923077 | Q12: 0 | R12: 0 | S12: =(M12*1)+(N12*3)-(Q12*2)-R12 -> 2
A13: Declan Rice | B13: 1 | C13: 0 | D13: 11 | E13: =IFERROR(B13/D13, 0) -> 0.090909091 | F13: 0 | G13: 0 | H13: =(B13*1)+(C13*3)-(F13*2)-G13 -> 1 | I13: =IFERROR(__xludf.DUMMYFUNCTION("""COMPUTED_VALUE"""),"Shevchenko") -> Shevchenko | J13: =IFERROR(__xludf.DUMMYFUNCTION("""COMPUTED_VALUE"""),14.0) -> 14 | K13: =IFERROR(__xludf.DUMMYFUNCTION("""COMPUTED_VALUE""")," (VDG)") -> (VDG) | L13: Tonali | M13: 1 | N13: 0 | O13: 15 | P13: =IFERROR(M13/O13, 0) -> 0.066666667 | Q13: 0 | R13: 0 | S13: =(M13*1)+(N13*3)-(Q13*2)-R13 -> 1
A14: Pedri | B14: 3 | C14: 0 | D14: 10 | E14: =IFERROR(B14/D14, 0) -> 0.3 | F14: 0 | G14: 0 | H14: =(B14*1)+(C14*3)-(F14*2)-G14 -> 3 | I14: =IFERROR(__xludf.DUMMYFUNCTION("""COMPUTED_VALUE"""),"Van Nistelrooij") -> Van Nistelrooij | J14: =IFERROR(__xludf.DUMMYFUNCTION("""COMPUTED_VALUE"""),13.0) -> 13 | K14: =IFERROR(__xludf.DUMMYFUNCTION("""COMPUTED_VALUE""")," (VDG)") -> (VDG) | L14: Fletcher | M14: 0 | N14: 0 | O14: 24 | P14: =IFERROR(M14/O14, 0) -> 0 | Q14: 0 | R14: 0 | S14: =(M14*1)+(N14*3)-(Q14*2)-R14 -> 0
A15: Mac Allister | B15: 0 | C15: 0 | D15: 15 | E15: =IFERROR(B15/D15, 0) -> 0 | F15: 1 | G15: 0 | H15: =(B15*1)+(C15*3)-(F15*2)-G15 -> -2 | I15: =IFERROR(__xludf.DUMMYFUNCTION("""COMPUTED_VALUE"""),"Mbappe") -> Mbappe | J15: =IFERROR(__xludf.DUMMYFUNCTION("""COMPUTED_VALUE"""),10.0) -> 10 | K15: =IFERROR(__xludf.DUMMYFUNCTION("""COMPUTED_VALUE""")," (VDG)") -> (VDG) | L15: Rodri | M15: 0 | N15: 0 | O15: 8 | P15: =IFERROR(M15/O15, 0) -> 0 | Q15: 0 | R15: 0 | S15: =(M15*1)+(N15*3)-(Q15*2)-R15 -> 0
A16: Odegaard | B16: 2 | C16: 0 | D16: 14 | E16: =IFERROR(B16/D16, 0) -> 0.14285714 | F16: 0 | G16: 0 | H16: =(B16*1)+(C16*3)-(F16*2)-G16 -> 2 | I16: =IFERROR(__xludf.DUMMYFUNCTION("""COMPUTED_VALUE"""),"Dani Olmo") -> Dani Olmo | J16: =IFERROR(__xludf.DUMMYFUNCTION("""COMPUTED_VALUE"""),10.0) -> 10 | K16: =IFERROR(__xludf.DUMMYFUNCTION("""COMPUTED_VALUE"""),"(SDC)") -> (SDC) | L16: Mac Allister | M16: 4 | N16: 0 | O16: 14 | P16: =IFERROR(M16/O16, 0) -> 0.28571429 | Q16: 0 | R16: 0 | S16: =(M16*1)+(N16*3)-(Q16*2)-R16 -> 4
A17: Kokcu | B17: 0 | C17: 0 | D17: 16 | E17: =IFERROR(B17/D17, 0) -> 0 | F17: 0 | G17: 0 | H17: =(B17*1)+(C17*3)-(F17*2)-G17 -> 0 | I17: =IFERROR(__xludf.DUMMYFUNCTION("""COMPUTED_VALUE"""),"Van Nistelrooy") -> Van Nistelrooy | J17: =IFERROR(__xludf.DUMMYFUNCTION("""COMPUTED_VALUE"""),7.0) -> 7 | K17: =IFERROR(__xludf.DUMMYFUNCTION("""COMPUTED_VALUE"""),"(SDC)") -> (SDC) | L17: Pedri | M17: 4 | N17: 0 | O17: 20 | P17: =IFERROR(M17/O17, 0) -> 0.2 | Q17: 0 | R17: 0 | S17: =(M17*1)+(N17*3)-(Q17*2)-R17 -> 4
A18: Kimmich | B18: 2 | C18: 0 | D18: 14 | E18: =IFERROR(B18/D18, 0) -> 0.14285714 | F18: 0 | G18: 0 | H18: =(B18*1)+(C18*3)-(F18*2)-G18 -> 2 | I18: =IFERROR(__xludf.DUMMYFUNCTION("""COMPUTED_VALUE"""),"Vieri") -> Vieri | J18: =IFERROR(__xludf.DUMMYFUNCTION("""COMPUTED_VALUE"""),7.0) -> 7 | K18: =IFERROR(__xludf.DUMMYFUNCTION("""COMPUTED_VALUE"""),"(SDC)") -> (SDC) | L18: Enzo Fernandez | M18: 3 | N18: 0 | O18: 17 | P18: =IFERROR(M18/O18, 0) -> 0.17647059 | Q18: 1 | R18: 0 | S18: =(M18*1)+(N18*3)-(Q18*2)-R18 -> 1
A19: Steven Gerard | B19: 1 | C19: 0 | D19: 6 | E19: =B19/D19 -> 0.16666667 | F19: 0 | G19: 0 | H19: =(B19*1)+(C19*3)-(F19*2)-G19 -> 1 | I19: =IFERROR(__xludf.DUMMYFUNCTION("""COMPUTED_VALUE"""),"Dembele") -> Dembele | J19: =IFERROR(__xludf.DUMMYFUNCTION("""COMPUTED_VALUE"""),6.0) -> 6 | K19: =IFERROR(__xludf.DUMMYFUNCTION("""COMPUTED_VALUE""")," (VDG)") -> (VDG) | L19: Dani Olmo | M19: 10 | N19: 0 | O19: 24 | P19: =IFERROR(M19/O19, 0) -> 0.41666667 | Q19: 0 | R19: 0 | S19: =(M19*1)+(N19*3)-(Q19*2)-R19 -> 10
A20: Totti | B20: 3 | C20: 0 | D20: 10 | E20: =IFERROR(B20/D20, 0) -> 0.3 | F20: 0 | G20: 0 | H20: =(B20*1)+(C20*3)-(F20*2)-G20 -> 3 | L20: Messi | M20: 6 | N20: 0 | O20: 19 | P20: =IFERROR(M20/O20, 0) -> 0.31578947 | Q20: 0 | R20: 0 | S20: =(M20*1)+(N20*3)-(Q20*2)-R20 -> 6
A21: De Bruyne | B21: 2 | C21: 0 | D21: 12 | E21: =IFERROR(B21/D21, 0) -> 0.16666667 | F21: 0 | G21: 0 | H21: =(B21*1)+(C21*3)-(F21*2)-G21 -> 2 | I21: MÁXIMOS GOLEADORES HISTÓRICOS | L21: Neymar | M21: 1 | N21: 0 | O21: 5 | P21: =IFERROR(M21/O21, 0) -> 0.2 | Q21: 0 | R21: 0 | S21: =(M21*1)+(N21*3)-(Q21*2)-R21 -> 1
A22: Neymar | B22: 5 | C22: 0 | D22: 15 | E22: =IFERROR(B22/D22, 0) -> 0.33333333 | F22: 0 | G22: 0 | H22: =(B22*1)+(C22*3)-(F22*2)-G22 -> 5 | I22: Jugador | J22: Cant. goles | K22: Equipo | L22: Van Nistelrooy | M22: 7 | N22: 0 | O22: 11 | P22: =IFERROR(M22/O22, 0) -> 0.63636364 | Q22: 0 | R22: 0 | S22: =(M22*1)+(N22*3)-(Q22*2)-R22 -> 7
A23: Bellingham | B23: 5 | C23: 0 | D23: 13 | E23: =IFERROR(B23/D23, 0) -> 0.38461538 | F23: 0 | G23: 0 | H23: =(B23*1)+(C23*3)-(F23*2)-G23 -> 5 | I23: =IFERROR(__xludf.DUMMYFUNCTION("IFERROR(SORTN(FILTER({A4:A50, B4:B50, IF(A4:A50="""", """", C2); L4:L50, M4:M50, IF(L4:L50="""", """", N2)}, {B4:B50; M4:M50} > 0), 10, 0, 2, FALSE), """")"),"Luis Diaz") -> Luis Diaz | J23: =IFERROR(__xludf.DUMMYFUNCTION("""COMPUTED_VALUE"""),37.0) -> 37 | K23: =IFERROR(__xludf.DUMMYFUNCTION("""COMPUTED_VALUE"""),"(SDC)") -> (SDC) | L23: Romario | M23: 1 | N23: 0 | O23: 6 | P23: =IFERROR(M23/O23, 0) -> 0.16666667 | Q23: 0 | R23: 0 | S23: =(M23*1)+(N23*3)-(Q23*2)-R23 -> 1
A24: Rosicky | B24: 3 | C24: 0 | D24: 6 | E24: =B24/D24 -> 0.5 | F24: 0 | G24: 0 | H24: =(B24*1)+(C24*3)-(F24*2)-G24 -> 3 | I24: =IFERROR(__xludf.DUMMYFUNCTION("""COMPUTED_VALUE"""),"Van Basten") -> Van Basten | J24: =IFERROR(__xludf.DUMMYFUNCTION("""COMPUTED_VALUE"""),36.0) -> 36 | K24: =IFERROR(__xludf.DUMMYFUNCTION("""COMPUTED_VALUE""")," (VDG)") -> (VDG) | L24: Luis Diaz | M24: 37 | N24: 0 | O24: 22 | P24: =IFERROR(M24/O24, 0) -> 1.6818182 | Q24: 0 | R24: 0 | S24: =(M24*1)+(N24*3)-(Q24*2)-R24 -> 37
A25: Mbappe | B25: 10 | C25: 0 | D25: 15 | E25: =IFERROR(B25/D25, 0) -> 0.66666667 | F25: 0 | G25: 0 | H25: =(B25*1)+(C25*3)-(F25*2)-G25 -> 10 | I25: =IFERROR(__xludf.DUMMYFUNCTION("""COMPUTED_VALUE"""),"Havertz") -> Havertz | J25: =IFERROR(__xludf.DUMMYFUNCTION("""COMPUTED_VALUE"""),36.0) -> 36 | K25: =IFERROR(__xludf.DUMMYFUNCTION("""COMPUTED_VALUE"""),"(SDC)") -> (SDC) | L25: Havertz | M25: 36 | N25: 0 | O25: 28 | P25: =IFERROR(M25/O25, 0) -> 1.2857143 | Q25: 2 | R25: 0 | S25: =(M25*1)+(N25*3)-(Q25*2)-R25 -> 32
A26: Van Basten | B26: 36 | C26: 0 | D26: 27 | E26: =IFERROR(B26/D26, 0) -> 1.3333333 | F26: 0 | G26: 0 | H26: =(B26*1)+(C26*3)-(F26*2)-G26 -> 36 | I26: =IFERROR(__xludf.DUMMYFUNCTION("""COMPUTED_VALUE"""),"Shevchenko") -> Shevchenko | J26: =IFERROR(__xludf.DUMMYFUNCTION("""COMPUTED_VALUE"""),14.0) -> 14 | K26: =IFERROR(__xludf.DUMMYFUNCTION("""COMPUTED_VALUE""")," (VDG)") -> (VDG) | L26: Lamine Yamal | M26: 6 | N26: 0 | O26: 10 | P26: =IFERROR(M26/O26, 0) -> 0.6 | Q26: 0 | R26: 0 | S26: =(M26*1)+(N26*3)-(Q26*2)-R26 -> 6
A27: Shevchenko | B27: 14 | C27: 0 | D27: 21 | E27: =IFERROR(B27/D27, 0) -> 0.66666667 | F27: 0 | G27: 0 | H27: =(B27*1)+(C27*3)-(F27*2)-G27 -> 14 | I27: =IFERROR(__xludf.DUMMYFUNCTION("""COMPUTED_VALUE"""),"Van Nistelrooij") -> Van Nistelrooij | J27: =IFERROR(__xludf.DUMMYFUNCTION("""COMPUTED_VALUE"""),13.0) -> 13 | K27: =IFERROR(__xludf.DUMMYFUNCTION("""COMPUTED_VALUE""")," (VDG)") -> (VDG) | L27: Diego Maradona | M27: 3 | N27: 0 | O27: 12 | P27: =IFERROR(M27/O27, 0) -> 0.25 | Q27: 0 | R27: 0 | S27: =(M27*1)+(N27*3)-(Q27*2)-R27 -> 3
A28: Dembele | B28: 6 | C28: 0 | D28: 10 | E28: =IFERROR(B28/D28, 0) -> 0.6 | F28: 0 | G28: 0 | H28: =(B28*1)+(C28*3)-(F28*2)-G28 -> 6 | I28: =IFERROR(__xludf.DUMMYFUNCTION("""COMPUTED_VALUE"""),"Mbappe") -> Mbappe | J28: =IFERROR(__xludf.DUMMYFUNCTION("""COMPUTED_VALUE"""),10.0) -> 10 | K28: =IFERROR(__xludf.DUMMYFUNCTION("""COMPUTED_VALUE""")," (VDG)") -> (VDG) | L28: Van Dijk | M28: 0 | N28: 0 | O28: 0 | P28: =IFERROR(M28/O28, 0) -> 0 | Q28: 0 | R28: 0 | S28: =(M28*1)+(N28*3)-(Q28*2)-R28 -> 0
A29: Darwin Nuñez | B29: 3 | C29: 0 | D29: 6 | E29: =B29/D29 -> 0.5 | F29: 1 | G29: 0 | H29: =(B29*1)+(C29*3)-(F29*2)-G29 -> 1 | I29: =IFERROR(__xludf.DUMMYFUNCTION("""COMPUTED_VALUE"""),"Dani Olmo") -> Dani Olmo | J29: =IFERROR(__xludf.DUMMYFUNCTION("""COMPUTED_VALUE"""),10.0) -> 10 | K29: =IFERROR(__xludf.DUMMYFUNCTION("""COMPUTED_VALUE"""),"(SDC)") -> (SDC) | L29: Bellingham | M29: 2 | N29: 0 | O29: 4 | P29: =IFERROR(M29/O29, 0) -> 0.5 | Q29: 0 | R29: 0 | S29: =(M29*1)+(N29*3)-(Q29*2)-R29 -> 2
A30: Rummeniegge | B30: 0 | C30: 0 | D30: 2 | E30: =IFERROR(B30/D30, 0) -> 0 | F30: 0 | G30: 0 | H30: =(B30*1)+(C30*3)-(F30*2)-G30 -> 0 | I30: =IFERROR(__xludf.DUMMYFUNCTION("""COMPUTED_VALUE"""),"Van Nistelrooy") -> Van Nistelrooy | J30: =IFERROR(__xludf.DUMMYFUNCTION("""COMPUTED_VALUE"""),7.0) -> 7 | K30: =IFERROR(__xludf.DUMMYFUNCTION("""COMPUTED_VALUE"""),"(SDC)") -> (SDC) | L30: Vieri | M30: 7 | N30: 0 | O30: 11 | P30: =IFERROR(M30/O30, 0) -> 0.63636364 | Q30: 0 | R30: 0 | S30: =(M30*1)+(N30*3)-(Q30*2)-R30 -> 7
A31: Gabriel Jesus | B31: 0 | C31: 0 | D31: 1 | E31: =IFERROR(B31/D31, 0) -> 0 | F31: 0 | G31: 0 | H31: =(B31*1)+(C31*3)-(F31*2)-G31 -> 0 | I31: =IFERROR(__xludf.DUMMYFUNCTION("""COMPUTED_VALUE"""),"Vieri") -> Vieri | J31: =IFERROR(__xludf.DUMMYFUNCTION("""COMPUTED_VALUE"""),7.0) -> 7 | K31: =IFERROR(__xludf.DUMMYFUNCTION("""COMPUTED_VALUE"""),"(SDC)") -> (SDC) | L31: Rice | M31: 0 | N31: 0 | O31: 3 | P31: =IFERROR(M31/O31, 0) -> 0 | Q31: 0 | R31: 0 | S31: =(M31*1)+(N31*3)-(Q31*2)-R31 -> 0
A32: Van Nistelrooij | B32: 13 | C32: 0 | D32: 16 | E32: =IFERROR(B32/D32, 0) -> 0.8125 | F32: 0 | G32: 0 | H32: =(B32*1)+(C32*3)-(F32*2)-G32 -> 13 | I32: =IFERROR(__xludf.DUMMYFUNCTION("""COMPUTED_VALUE"""),"Dembele") -> Dembele | J32: =IFERROR(__xludf.DUMMYFUNCTION("""COMPUTED_VALUE"""),6.0) -> 6 | K32: =IFERROR(__xludf.DUMMYFUNCTION("""COMPUTED_VALUE""")," (VDG)") -> (VDG) | L32: Paredes | M32: 0 | N32: 0 | O32: 2 | P32: =IFERROR(M32/O32, 0) -> 0 | Q32: 0 | R32: 0 | S32: =(M32*1)+(N32*3)-(Q32*2)-R32 -> 0
A33: Osimhen | B33: 0 | C33: 0 | D33: 2 | E33: =B33/D33 -> 0 | F33: 0 | G33: 0 | H33: =(B33*1)+(C33*3)-(F33*2)-G33 -> 0 | P33: =IFERROR(M33/O33, 0) -> 0 | R33: 0 | S33: =(M33*1)+(N33*3)-(Q33*2)-R33 -> 0
A34: J. Alvarez | B34: 0 | C34: 0 | D34: 5 | E34: =IFERROR(B34/D34, 0) -> 0 | F34: 0 | G34: 0 | H34: =(B34*1)+(C34*3)-(F34*2)-G34 -> 0 | P34: =IFERROR(M34/O34, 0) -> 0 | R34: 0 | S34: =(M34*1)+(N34*3)-(Q34*2)-R34 -> 0
A35: Montiel | G35: 0 | H35: =(B35*1)+(C35*3)-(F35*2)-G35 -> 0 | P35: =IFERROR(M35/O35, 0) -> 0 | R35: 0 | S35: =(M35*1)+(N35*3)-(Q35*2)-R35 -> 0
A36: Silvestre | G36: 0 | H36: =(B36*1)+(C36*3)-(F36*2)-G36 -> 0 | P36: =IFERROR(M36/O36, 0) -> 0 | R36: 0 | S36: =(M36*1)+(N36*3)-(Q36*2)-R36 -> 0
G37: 0 | H37: =(B37*1)+(C37*3)-(F37*2)-G37 -> 0 | P37: =IFERROR(M37/O37, 0) -> 0 | R37: 0 | S37: =(M37*1)+(N37*3)-(Q37*2)-R37 -> 0
G38: 0 | H38: =(B38*1)+(C38*3)-(F38*2)-G38 -> 0 | P38: =IFERROR(M38/O38, 0) -> 0 | R38: 0 | S38: =(M38*1)+(N38*3)-(Q38*2)-R38 -> 0
G39: 0 | H39: =(B39*1)+(C39*3)-(F39*2)-G39 -> 0 | P39: =IFERROR(M39/O39, 0) -> 0 | R39: 0 | S39: =(M39*1)+(N39*3)-(Q39*2)-R39 -> 0
G40: 0 | H40: =(B40*1)+(C40*3)-(F40*2)-G40 -> 0 | P40: =IFERROR(M40/O40, 0) -> 0 | R40: 0 | S40: =(M40*1)+(N40*3)-(Q40*2)-R40 -> 0
...

Sheet TEMPORADA 2
A1: SUPERCLASICO PES
A2: VIUDAS DE GALLARDO | C2: (VDG) | I2: CRITERIOS BALÓN DE ORO | L2: SOLDADO DE COUDET | N2: (SDC)
A3: JUGADORES | B3: CANT. GOLES | C3: MVP's | D3: JUGADOS | E3: PROM. GOL | F3: TARJ. ROJAS | G3: TARJ. AMARILLA | H3: PBDO | I3: MVP | K3: suma 3 | L3: JUGADORES | M3: CANT. GOLES | N3: MVP´s | O3: JUGADOS | P3: PROM. GOL | Q3: TARJ. ROJAS | R3: TARJ. AMARILLA | S3: PBDO
A4: Khan | B4: 0 | C4: 0 | D4: 0 | E4: =IFERROR(B4/D4, 0) -> 0 | F4: 0 | G4: 0 | H4: =(B4)+(C4*3)-G4-(F4*2) -> 0 | I4: GOL | K4: suma 1 | L4: Cech | M4: 0 | N4: 0 | O4: 0 | P4: =IFERROR(M4/O4, 0) -> 0 | Q4: 0 | R4: 0 | S4: =(M4*1)+(N4*3)-(Q4*2)-R4 -> 0
A5: Peruzzi | B5: 0 | C5: 0 | D5: 0 | E5: =IFERROR(B5/D5, 0) -> 0 | F5: 0 | G5: 0 | H5: =(B5*1)+(C5*3)-(F5*2)-G5 -> 0 | I5: AMARILLA | K5: resta 1 | L5: Puyol | M5: 0 | N5: 0 | O5: 0 | P5: =IFERROR(M5/O5, 0) -> 0 | Q5: 0 | R5: 0 | S5: =(M5*1)+(N5*3)-(Q5*2)-R5 -> 0
A6: Van Dijk | B6: 0 | C6: 0 | D6: 0 | E6: =IFERROR(B6/D6, 0) -> 0 | F6: 0 | G6: 0 | H6: =(B6*1)+(C6*3)-(F6*2)-G6 -> 0 | I6: ROJA | K6: resta 2 | L6: Vermaelen | M6: 0 | N6: 0 | O6: 0 | P6: =IFERROR(M6/O6, 0) -> 0 | Q6: 0 | R6: 0 | S6: =(M6*1)+(N6*3)-(Q6*2)-R6 -> 0
A7: Mancini | B7: 0 | C7: 0 | D7: 0 | E7: =IFERROR(B7/D7, 0) -> 0 | F7: 0 | G7: 0 | H7: =(B7*1)+(C7*3)-(F7*2)-G7 -> 0 | L7: Beckenbauer | M7: 0 | N7: 0 | O7: 0 | P7: =IFERROR(M7/O7, 0) -> 0 | Q7: 0 | R7: 0 | S7: =(M7*1)+(N7*3)-(Q7*2)-R7 -> 0
A8: Saliba | B8: 0 | C8: 0 | D8: 0 | E8: =IFERROR(B8/D8, 0) -> 0 | F8: 0 | G8: 0 | H8: =(B8*1)+(C8*3)-(F8*2)-G8 -> 0 | I8: Suma de puntos Balón de ORO | L8: Bastoni | M8: 0 | N8: 0 | O8: 0 | P8: =IFERROR(M8/O8, 0) -> 0 | Q8: 0 | R8: 0 | S8: =(M8*1)+(N8*3)-(Q8*2)-R8 -> 0
A9: Huijsen | B9: 0 | C9: 0 | D9: 0 | E9: =IFERROR(B9/D9, 0) -> 0 | F9: 0 | G9: 0 | H9: =(B9*1)+(C9*3)-(F9*2)-G9 -> 0 | I9: Jugador | J9: Puntaje | K9: Equipo | L9: Kounde | M9: 0 | N9: 0 | O9: 0 | P9: =IFERROR(M9/O9, 0) -> 0 | Q9: 0 | R9: 0 | S9: =(M9*1)+(N9*3)-(Q9*2)-R9 -> 0
A10: Matty Cash | B10: 0 | C10: 0 | D10: 0 | E10: =IFERROR(B10/D10, 0) -> 0 | F10: 0 | G10: 0 | H10: =(B10*1)+(C10*3)-(F10*2)-G10 -> 0 | I10: =IFERROR(__xludf.DUMMYFUNCTION("IFERROR(SORTN(FILTER({A4:A40, H4:H40, IF(A4:A40="""", """", C2); L4:L40, S4:S40, IF(L4:L40="""", """", N2)}, {H4:H40; S4:S40} > 0), 10, 0, 2, FALSE), """")"),"") | L10: Silvestre | M10: 0 | N10: 0 | O10: 0 | P10: =IFERROR(M10/O10, 0) -> 0 | Q10: 0 | R10: 0 | S10: =(M10*1)+(N10*3)-(Q10*2)-R10 -> 0
A11: Grimaldo | B11: 0 | C11: 0 | D11: 0 | E11: =IFERROR(B11/D11, 0) -> 0 | F11: 0 | G11: 0 | H11: =(B11*1)+(C11*3)-(F11*2)-G11 -> 0 | L11: Gvardiol | M11: 0 | N11: 0 | O11: 0 | P11: =IFERROR(M11/O11, 0) -> 0 | Q11: 0 | R11: 0 | S11: =(M11*1)+(N11*3)-(Q11*2)-R11 -> 0
A12: Rijkaard | B12: 0 | C12: 0 | D12: 0 | E12: =IFERROR(B12/D12, 0) -> 0 | F12: 0 | G12: 0 | H12: =(B12*1)+(C12*3)-(F12*2)-G12 -> 0 | L12: Cafú | M12: 0 | N12: 0 | O12: 0 | P12: =IFERROR(M12/O12, 0) -> 0 | Q12: 0 | R12: 0 | S12: =(M12*1)+(N12*3)-(Q12*2)-R12 -> 0
A13: Declan Rice | B13: 0 | C13: 0 | D13: 0 | E13: =IFERROR(B13/D13, 0) -> 0 | F13: 0 | G13: 0 | H13: =(B13*1)+(C13*3)-(F13*2)-G13 -> 0 | L13: Tonali | M13: 0 | N13: 0 | O13: 0 | P13: =IFERROR(M13/O13, 0) -> 0 | Q13: 0 | R13: 0 | S13: =(M13*1)+(N13*3)-(Q13*2)-R13 -> 0
A14: Pedri | B14: 0 | C14: 0 | D14: 0 | E14: =IFERROR(B14/D14, 0) -> 0 | F14: 0 | G14: 0 | H14: =(B14*1)+(C14*3)-(F14*2)-G14 -> 0 | L14: Fletcher | M14: 0 | N14: 0 | O14: 0 | P14: =IFERROR(M14/O14, 0) -> 0 | Q14: 0 | R14: 0 | S14: =(M14*1)+(N14*3)-(Q14*2)-R14 -> 0
A15: Mac Allister | B15: 0 | C15: 0 | D15: 0 | E15: =IFERROR(B15/D15, 0) -> 0 | F15: 0 | G15: 0 | H15: =(B15*1)+(C15*3)-(F15*2)-G15 -> 0 | L15: Rodri | M15: 0 | N15: 0 | O15: 0 | P15: =IFERROR(M15/O15, 0) -> 0 | Q15: 0 | R15: 0 | S15: =(M15*1)+(N15*3)-(Q15*2)-R15 -> 0
A16: Odegaard | B16: 0 | C16: 0 | D16: 0 | E16: =IFERROR(B16/D16, 0) -> 0 | F16: 0 | G16: 0 | H16: =(B16*1)+(C16*3)-(F16*2)-G16 -> 0 | L16: Mac Allister | M16: 0 | N16: 0 | O16: 0 | P16: =IFERROR(M16/O16, 0) -> 0 | Q16: 0 | R16: 0 | S16: =(M16*1)+(N16*3)-(Q16*2)-R16 -> 0
A17: Kokcu | B17: 0 | C17: 0 | D17: 0 | E17: =IFERROR(B17/D17, 0) -> 0 | F17: 0 | G17: 0 | H17: =(B17*1)+(C17*3)-(F17*2)-G17 -> 0 | L17: Pedri | M17: 0 | N17: 0 | O17: 0 | P17: =IFERROR(M17/O17, 0) -> 0 | Q17: 0 | R17: 0 | S17: =(M17*1)+(N17*3)-(Q17*2)-R17 -> 0
A18: Kimmich | B18: 0 | C18: 0 | D18: 0 | E18: =IFERROR(B18/D18, 0) -> 0 | F18: 0 | G18: 0 | H18: =(B18*1)+(C18*3)-(F18*2)-G18 -> 0 | L18: Enzo Fernandez | M18: 0 | N18: 0 | O18: 0 | P18: =IFERROR(M18/O18, 0) -> 0 | Q18: 0 | R18: 0 | S18: =(M18*1)+(N18*3)-(Q18*2)-R18 -> 0
A19: Steven Gerard | B19: 0 | C19: 0 | D19: 0 | E19: =B19/D19 -> #DIV/0! | F19: 0 | G19: 0 | H19: =(B19*1)+(C19*3)-(F19*2)-G19 -> 0 | L19: Dani Olmo | M19: 0 | N19: 0 | O19: 0 | P19: =IFERROR(M19/O19, 0) -> 0 | Q19: 0 | R19: 0 | S19: =(M19*1)+(N19*3)-(Q19*2)-R19 -> 0
A20: Totti | B20: 0 | C20: 0 | D20: 0 | E20: =IFERROR(B20/D20, 0) -> 0 | F20: 0 | G20: 0 | H20: =(B20*1)+(C20*3)-(F20*2)-G20 -> 0 | L20: Messi | M20: 0 | N20: 0 | O20: 0 | P20: =IFERROR(M20/O20, 0) -> 0 | Q20: 0 | R20: 0 | S20: =(M20*1)+(N20*3)-(Q20*2)-R20 -> 0
A21: De Bruyne | B21: 0 | C21: 0 | D21: 0 | E21: =IFERROR(B21/D21, 0) -> 0 | F21: 0 | G21: 0 | H21: =(B21*1)+(C21*3)-(F21*2)-G21 -> 0 | I21: MÁXIMOS GOLEADORES TEMPORADA | L21: Neymar | M21: 0 | N21: 0 | O21: 0 | P21: =IFERROR(M21/O21, 0) -> 0 | Q21: 0 | R21: 0 | S21: =(M21*1)+(N21*3)-(Q21*2)-R21 -> 0
A22: Neymar | B22: 0 | C22: 0 | D22: 0 | E22: =IFERROR(B22/D22, 0) -> 0 | G22: 0 | H22: =(B22*1)+(C22*3)-(F22*2)-G22 -> 0 | I22: Jugador | J22: Cant. goles | K22: Equipo | L22: Van Nistelrooy | M22: 0 | N22: 0 | O22: 0 | P22: =IFERROR(M22/O22, 0) -> 0 | Q22: 0 | R22: 0 | S22: =(M22*1)+(N22*3)-(Q22*2)-R22 -> 0
A23: Bellingham | B23: 0 | C23: 0 | D23: 0 | E23: =IFERROR(B23/D23, 0) -> 0 | F23: 0 | G23: 0 | H23: =(B23*1)+(C23*3)-(F23*2)-G23 -> 0 | I23: =IFERROR(__xludf.DUMMYFUNCTION("IFERROR(SORTN(FILTER({A4:A50, B4:B50, IF(A4:A50="""", """", C2); L4:L50, M4:M50, IF(L4:L50="""", """", N2)}, {B4:B50; M4:M50} > 0), 10, 0, 2, FALSE), """")"),"") | L23: Romario | M23: 0 | N23: 0 | O23: 0 | P23: =IFERROR(M23/O23, 0) -> 0 | Q23: 0 | R23: 0 | S23: =(M23*1)+(N23*3)-(Q23*2)-R23 -> 0
A24: Rosicky | B24: 0 | C24: 0 | D24: 0 | E24: =B24/D24 -> #DIV/0! | F24: 0 | G24: 0 | H24: =(B24*1)+(C24*3)-(F24*2)-G24 -> 0 | L24: Luis Diaz | M24: 0 | N24: 0 | O24: 0 | P24: =IFERROR(M24/O24, 0) -> 0 | Q24: 0 | R24: 0 | S24: =(M24*1)+(N24*3)-(Q24*2)-R24 -> 0
A25: Mbappe | B25: 0 | C25: 0 | D25: 0 | E25: =IFERROR(B25/D25, 0) -> 0 | F25: 0 | G25: 0 | H25: =(B25*1)+(C25*3)-(F25*2)-G25 -> 0 | L25: Havertz | M25: 0 | N25: 0 | O25: 0 | P25: =IFERROR(M25/O25, 0) -> 0 | Q25: 0 | R25: 0 | S25: =(M25*1)+(N25*3)-(Q25*2)-R25 -> 0
A26: Van Basten | B26: 0 | C26: 0 | D26: 0 | E26: =IFERROR(B26/D26, 0) -> 0 | F26: 0 | G26: 0 | H26: =(B26*1)+(C26*3)-(F26*2)-G26 -> 0 | L26: Lamine Yamal | M26: 0 | N26: 0 | O26: 0 | P26: =IFERROR(M26/O26, 0) -> 0 | Q26: 0 | R26: 0 | S26: =(M26*1)+(N26*3)-(Q26*2)-R26 -> 0
A27: Shevchenko | B27: 0 | C27: 0 | D27: 0 | E27: =IFERROR(B27/D27, 0) -> 0 | F27: 0 | G27: 0 | H27: =(B27*1)+(C27*3)-(F27*2)-G27 -> 0 | L27: Diego Maradona | M27: 0 | N27: 0 | O27: 0 | P27: =IFERROR(M27/O27, 0) -> 0 | Q27: 0 | R27: 0 | S27: =(M27*1)+(N27*3)-(Q27*2)-R27 -> 0
A28: Dembele | B28: 0 | C28: 0 | D28: 0 | E28: =IFERROR(B28/D28, 0) -> 0 | F28: 0 | G28: 0 | H28: =(B28*1)+(C28*3)-(F28*2)-G28 -> 0 | L28: Van Dijk | M28: 0 | N28: 0 | O28: 0 | P28: =IFERROR(M28/O28, 0) -> 0 | Q28: 0 | R28: 0 | S28: =(M28*1)+(N28*3)-(Q28*2)-R28 -> 0
A29: Darwin Nuñez | B29: 0 | C29: 0 | D29: 0 | E29: =B29/D29 -> #DIV/0! | F29: 0 | G29: 0 | H29: =(B29*1)+(C29*3)-(F29*2)-G29 -> 0 | L29: Bellingham | M29: 0 | N29: 0 | O29: 0 | P29: =IFERROR(M29/O29, 0) -> 0 | Q29: 0 | R29: 0 | S29: =(M29*1)+(N29*3)-(Q29*2)-R29 -> 0
A30: Rummeniegge | B30: 0 | C30: 0 | D30: 0 | E30: =IFERROR(B30/D30, 0) -> 0 | F30: 0 | G30: 0 | H30: =(B30*1)+(C30*3)-(F30*2)-G30 -> 0 | L30: Vieri | M30: 0 | N30: 0 | O30: 0 | P30: =IFERROR(M30/O30, 0) -> 0 | Q30: 0 | R30: 0 | S30: =(M30*1)+(N30*3)-(Q30*2)-R30 -> 0
A31: Gabriel Jesus | B31: 0 | C31: 0 | D31: 0 | E31: =IFERROR(B31/D31, 0) -> 0 | F31: 0 | G31: 0 | H31: =(B31*1)+(C31*3)-(F31*2)-G31 -> 0 | L31: Rice | M31: 0 | N31: 0 | O31: 0 | P31: =IFERROR(M31/O31, 0) -> 0 | Q31: 0 | R31: 0 | S31: =(M31*1)+(N31*3)-(Q31*2)-R31 -> 0
A32: Van Nistelrooij | B32: 0 | C32: 0 | D32: 0 | E32: =IFERROR(B32/D32, 0) -> 0 | F32: 0 | G32: 0 | H32: =(B32*1)+(C32*3)-(F32*2)-G32 -> 0 | L32: Paredes | M32: 0 | N32: 0 | O32: 0 | P32: =IFERROR(M32/O32, 0) -> 0 | Q32: 0 | R32: 0 | S32: =(M32*1)+(N32*3)-(Q32*2)-R32 -> 0
A33: Osimhen | B33: 0 | C33: 0 | D33: 0 | E33: =B33/D33 -> #DIV/0! | F33: 0 | G33: 0 | H33: =(B33*1)+(C33*3)-(F33*2)-G33 -> 0 | P33: =IFERROR(M33/O33, 0) -> 0 | R33: 0 | S33: =(M33*1)+(N33*3)-(Q33*2)-R33 -> 0
A34: J. Alvarez | B34: 0 | C34: 0 | D34: 0 | E34: =IFERROR(B34/D34, 0) -> 0 | F34: 0 | G34: 0 | H34: =(B34*1)+(C34*3)-(F34*2)-G34 -> 0 | P34: =IFERROR(M34/O34, 0) -> 0 | R34: 0 | S34: =(M34*1)+(N34*3)-(Q34*2)-R34 -> 0
A35: Montiel | B35: 0 | C35: 0 | D35: 0 | F35: 0 | G35: 0 | H35: =(B35*1)+(C35*3)-(F35*2)-G35 -> 0 | P35: =IFERROR(M35/O35, 0) -> 0 | R35: 0 | S35: =(M35*1)+(N35*3)-(Q35*2)-R35 -> 0
A36: Silvestre | B36: 0 | C36: 0 | D36: 0 | F36: 0 | G36: 0 | H36: =(B36*1)+(C36*3)-(F36*2)-G36 -> 0 | P36: =IFERROR(M36/O36, 0) -> 0 | R36: 0 | S36: =(M36*1)+(N36*3)-(Q36*2)-R36 -> 0
G37: 0 | H37: =(B37*1)+(C37*3)-(F37*2)-G37 -> 0 | P37: =IFERROR(M37/O37, 0) -> 0 | R37: 0 | S37: =(M37*1)+(N37*3)-(Q37*2)-R37 -> 0
G38: 0 | H38: =(B38*1)+(C38*3)-(F38*2)-G38 -> 0 | P38: =IFERROR(M38/O38, 0) -> 0 | R38: 0 | S38: =(M38*1)+(N38*3)-(Q38*2)-R38 -> 0
G39: 0 | H39: =(B39*1)+(C39*3)-(F39*2)-G39 -> 0 | P39: =IFERROR(M39/O39, 0) -> 0 | R39: 0 | S39: =(M39*1)+(N39*3)-(Q39*2)-R39 -> 0
G40: 0 | H40: =(B40*1)+(C40*3)-(F40*2)-G40 -> 0 | P40: =IFERROR(M40/O40, 0) -> 0 | R40: 0 | S40: =(M40*1)+(N40*3)-(Q40*2)-R40 -> 0
...
